<?xml version="1.0" encoding="utf-8"?>
<robot name="smart_arm" xmlns:xacro="http://www.ros.org/wiki/xacro" >

  <link name="elbow_link">
    <inertial>
      <origin
        xyz="-0.000205770640037656 0.000108385036079905 0.103139863094332"
        rpy="0 0 0" />
      <mass
        value="0.295493853268353" />
      <inertia
        ixx="0.000483065500673909"
        ixy="-3.31332778426896E-05"
        ixz="-7.20159423734281E-07"
        iyy="0.0003469525375019"
        iyz="-3.22980553305975E-06"
        izz="0.000501419614441105" />
    </inertial>
    <visual>
      <origin
        xyz="0 0 0"
        rpy="0 0 0" />
      <geometry>
        <mesh
          filename="package://smart_arm_description/meshes/elbow_link.STL" />
      </geometry>
      <material
        name="">
        <color
          rgba="0.792156862745098 0.819607843137255 0.933333333333333 1" />
      </material>
    </visual>
    <collision>
      <origin
        xyz="0 0 0"
        rpy="0 0 0" />
      <geometry>
        <mesh
          filename="package://smart_arm_description/meshes/elbow_link.STL" />
      </geometry>
    </collision>
  </link>

  <link  name="wrist_link">
    <inertial>
      <origin
        xyz="-0.000107664352745035 -0.014691017881254 0.0475352652097448"
        rpy="0 0 0" />
      <mass
        value="0.0703349976668528" />
      <inertia
        ixx="8.33145956878074E-05"
        ixy="7.39496138280138E-08"
        ixz="3.04356429676113E-07"
        iyy="5.95941312686552E-05"
        iyz="-1.95191463116659E-05"
        izz="2.69797202551765E-05" />
    </inertial>
    <visual>
      <origin
        xyz="0 0 0"
        rpy="0 0 0" />
      <geometry>
        <mesh
          filename="package://smart_arm_description/meshes/wrist_link.STL" />
      </geometry>
      <material
        name="">
        <color
          rgba="0.792156862745098 0.819607843137255 0.933333333333333 1" />
      </material>
    </visual>
    <collision>
      <origin
        xyz="0 0 0"
        rpy="0 0 0" />
      <geometry>
        <mesh
          filename="package://smart_arm_description/meshes/wrist_link.STL" />
      </geometry>
    </collision>
  </link>

  <link name="wrist_lower_link">
    <inertial>
      <origin
        xyz="-0.0308791426702174 0.00349683553043886 0.0203486593271935"
        rpy="0 0 0" />
      <mass
        value="0.0179601480402659" />
      <inertia
        ixx="3.35618082767684E-06"
        ixy="2.00012150714684E-07"
        ixz="1.29580489766705E-06"
        iyy="4.56681598704689E-06"
        iyz="-3.93596882945118E-07"
        izz="2.21180778937816E-06" />
    </inertial>
    <visual>
      <origin
        xyz="0 0 0"
        rpy="0 0 0" />
      <geometry>
        <mesh
          filename="package://smart_arm_description/meshes/wrist_lower_link.STL" />
      </geometry>
      <material
        name="">
        <color
          rgba="0.792156862745098 0.819607843137255 0.933333333333333 1" />
      </material>
    </visual>
    <collision>
      <origin
        xyz="0 0 0"
        rpy="0 0 0" />
      <geometry>
        <mesh
          filename="package://smart_arm_description/meshes/wrist_lower_link.STL" />
      </geometry>
    </collision>
  </link>

  <link name="pinky_1_link">
    <inertial>
      <origin
        xyz="-0.00522866781159657 -0.0149787954896174 0.00244494110809049"
        rpy="0 0 0" />
      <mass
        value="0.00269063416432976" />
      <inertia
        ixx="1.20242598540253E-07"
        ixy="6.14041884687285E-12"
        ixz="5.8215008319749E-11"
        iyy="8.94283979714206E-08"
        iyz="7.05706982971785E-09"
        izz="1.37183208246673E-07" />
    </inertial>
    <visual>
      <origin
        xyz="0 0 0"
        rpy="0 0 0" />
      <geometry>
        <mesh
          filename="package://smart_arm_description/meshes/pinky_1_link.STL" />
      </geometry>
      <material
        name="">
        <color
          rgba="0.792156862745098 0.819607843137255 0.933333333333333 1" />
      </material>
    </visual>
    <collision>
      <origin
        xyz="0 0 0"
        rpy="0 0 0" />
      <geometry>
        <mesh
          filename="package://smart_arm_description/meshes/pinky_1_link.STL" />
      </geometry>
    </collision>
  </link>
  
  <link name="pinky_2_link">
    <inertial>
      <origin
        xyz="-0.00512598077996924 0.00901128431388447 -0.000581173891856732"
        rpy="0 0 0" />
      <mass
        value="0.00171948798725875" />
      <inertia
        ixx="4.38399098177655E-08"
        ixy="5.73443666856809E-10"
        ixz="-1.02208225680834E-10"
        iyy="3.88616206091108E-08"
        iyz="4.09208074266455E-09"
        izz="4.31403255685011E-08" />
    </inertial>
    <visual>
      <origin
        xyz="0 0 0"
        rpy="0 0 0" />
      <geometry>
        <mesh
          filename="package://smart_arm_description/meshes/pinky_2_link.STL" />
      </geometry>
      <material
        name="">
        <color
          rgba="0.792156862745098 0.819607843137255 0.933333333333333 1" />
      </material>
    </visual>
    <collision>
      <origin
        xyz="0 0 0"
        rpy="0 0 0" />
      <geometry>
        <mesh
          filename="package://smart_arm_description/meshes/pinky_2_link.STL" />
      </geometry>
    </collision>
  </link>

  <link name="pinky_3_link">
    <inertial>
      <origin
        xyz="-0.00433667543015367 0.0081019823699609 -0.00505664472792688"
        rpy="0 0 0" />
      <mass
        value="0.00142350343627245" />
      <inertia
        ixx="3.38966058052191E-08"
        ixy="-4.50552956352627E-12"
        ixz="1.68997250065103E-11"
        iyy="2.9028388995604E-08"
        iyz="4.53049886719614E-09"
        izz="2.81288327170812E-08" />
    </inertial>
    <visual>
      <origin
        xyz="0 0 0"
        rpy="0 0 0" />
      <geometry>
        <mesh
          filename="package://smart_arm_description/meshes/pinky_3_link.STL" />
      </geometry>
      <material
        name="">
        <color
          rgba="0.792156862745098 0.819607843137255 0.933333333333333 1" />
      </material>
    </visual>
    <collision>
      <origin
        xyz="0 0 0"
        rpy="0 0 0" />
      <geometry>
        <mesh
          filename="package://smart_arm_description/meshes/pinky_3_link.STL" />
      </geometry>
    </collision>
  </link>

  <link name="wrist_middle_link">
    <inertial>
      <origin
        xyz="-0.059351810470969 0.00297685937771368 0.0174911833138776"
        rpy="0 0 0" />
      <mass
        value="0.0133231625794088" />
      <inertia
        ixx="1.92896908777582E-06"
        ixy="7.95493573698368E-08"
        ixz="5.23952379047857E-07"
        iyy="2.50637427994164E-06"
        iyz="-1.97278566939604E-07"
        izz="1.29114139991389E-06" />
    </inertial>
    <visual>
      <origin
        xyz="0 0 0"
        rpy="0 0 0" />
      <geometry>
        <mesh
          filename="package://smart_arm_description/meshes/wrist_middle_link.STL" />
      </geometry>
      <material
        name="">
        <color
          rgba="0.792156862745098 0.819607843137255 0.933333333333333 1" />
      </material>
    </visual>
    <collision>
      <origin
        xyz="0 0 0"
        rpy="0 0 0" />
      <geometry>
        <mesh
          filename="package://smart_arm_description/meshes/wrist_middle_link.STL" />
      </geometry>
    </collision>
  </link>

  <link name="ring_1_link">
    <inertial>
      <origin
        xyz="-0.0062731487203958 0.0178677991712861 -0.00350735852997959"
        rpy="0 0 0" />
      <mass
        value="0.00464662723898721" />
      <inertia
        ixx="2.9890299993066E-07"
        ixy="-1.98178385884489E-11"
        ixz="-1.44064397803553E-10"
        iyy="2.23548899653077E-07"
        iyz="2.13065720147208E-08"
        izz="3.39770028839746E-07" />
    </inertial>
    <visual>
      <origin
        xyz="0 0 0"
        rpy="0 0 0" />
      <geometry>
        <mesh
          filename="package://smart_arm_description/meshes/ring_1_link.STL" />
      </geometry>
      <material
        name="">
        <color
          rgba="0.792156862745098 0.819607843137255 0.933333333333333 1" />
      </material>
    </visual>
    <collision>
      <origin
        xyz="0 0 0"
        rpy="0 0 0" />
      <geometry>
        <mesh
          filename="package://smart_arm_description/meshes/ring_1_link.STL" />
      </geometry>
    </collision>
  </link>

  <link name="ring_2_link">
    <inertial>
      <origin
        xyz="-0.00599442209155701 0.0109099257977444 -0.000450484446247124"
        rpy="0 0 0" />
      <mass
        value="0.00296941783525498" />
      <inertia
        ixx="1.09028461614364E-07"
        ixy="4.53930271304141E-12"
        ixz="-4.29160978497908E-12"
        iyy="9.46598294680744E-08"
        iyz="9.00687858749085E-09"
        izz="1.09127096165152E-07" />
    </inertial>
    <visual>
      <origin
        xyz="0 0 0"
        rpy="0 0 0" />
      <geometry>
        <mesh
          filename="package://smart_arm_description/meshes/ring_2_link.STL" />
      </geometry>
      <material
        name="">
        <color
          rgba="0.792156862745098 0.819607843137255 0.933333333333333 1" />
      </material>
    </visual>
    <collision>
      <origin
        xyz="0 0 0"
        rpy="0 0 0" />
      <geometry>
        <mesh
          filename="package://smart_arm_description/meshes/ring_2_link.STL" />
      </geometry>
    </collision>
  </link>
  
  <link name="ring_3_link">
    <inertial>
      <origin
        xyz="-0.00520292510737917 0.0114659419405466 -0.000387345885786594"
        rpy="0 0 0" />
      <mass
        value="0.0024583065139303" />
      <inertia
        ixx="8.42582776799548E-08"
        ixy="-3.12990012358554E-11"
        ixz="3.0662688306369E-11"
        iyy="6.18419461954836E-08"
        iyz="6.59258772398117E-09"
        izz="8.02378471172367E-08" />
    </inertial>
    <visual>
      <origin
        xyz="0 0 0"
        rpy="0 0 0" />
      <geometry>
        <mesh
          filename="package://smart_arm_description/meshes/ring_3_link.STL" />
      </geometry>
      <material
        name="">
        <color
          rgba="0.792156862745098 0.819607843137255 0.933333333333333 1" />
      </material>
    </visual>
    <collision>
      <origin
        xyz="0 0 0"
        rpy="0 0 0" />
      <geometry>
        <mesh
          filename="package://smart_arm_description/meshes/ring_3_link.STL" />
      </geometry>
    </collision>
  </link>

  <link name="wrist_upper_link">
    <inertial>
      <origin
        xyz="-0.0366550772980235 0.00764946692547766 -0.0140269197547968"
        rpy="0 0 0" />
      <mass
        value="0.0103243269131143" />
      <inertia
        ixx="7.48338998818573E-07"
        ixy="-4.20182846150398E-08"
        ixz="6.08546051037344E-08"
        iyy="1.06628115984118E-06"
        iyz="6.39209500929198E-08"
        izz="9.79175522091434E-07" />
    </inertial>
    <visual>
      <origin
        xyz="0 0 0"
        rpy="0 0 0" />
      <geometry>
        <mesh
          filename="package://smart_arm_description/meshes/wrist_upper_link.STL" />
      </geometry>
      <material
        name="">
        <color
          rgba="0.792156862745098 0.819607843137255 0.933333333333333 1" />
      </material>
    </visual>
    <collision>
      <origin
        xyz="0 0 0"
        rpy="0 0 0" />
      <geometry>
        <mesh
          filename="package://smart_arm_description/meshes/wrist_upper_link.STL" />
      </geometry>
    </collision>
  </link>

  <link  name="thumb_1_link">
    <inertial>
      <origin
        xyz="-0.00733195290859857 0.0123357237864767 0.0124289912891914"
        rpy="0 0 0" />
      <mass
        value="0.00578742546735096" />
      <inertia
        ixx="2.9022059126798E-07"
        ixy="-9.85448053363409E-14"
        ixz="-4.41249917228209E-13"
        iyy="3.54248074807296E-07"
        iyz="-1.93352692370391E-08"
        izz="3.54050996721444E-07" />
    </inertial>
    <visual>
      <origin
        xyz="0 0 0"
        rpy="0 0 0" />
      <geometry>
        <mesh
          filename="package://smart_arm_description/meshes/thumb_1_link.STL" />
      </geometry>
      <material
        name="">
        <color
          rgba="0.792156862745098 0.819607843137255 0.933333333333333 1" />
      </material>
    </visual>
    <collision>
      <origin
        xyz="0 0 0"
        rpy="0 0 0" />
      <geometry>
        <mesh
          filename="package://smart_arm_description/meshes/thumb_1_link.STL" />
      </geometry>
    </collision>
  </link>

  <link  name="thumb_2_link">
    <inertial>
      <origin
        xyz="-0.0064568457068869 0.0102775150349664 0.00846428836658635"
        rpy="0 0 0" />
      <mass
        value="0.00408607534767685" />
      <inertia
        ixx="1.95951404716398E-07"
        ixy="-7.73858676630385E-11"
        ixz="1.1896278633326E-10"
        iyy="1.85983967135428E-07"
        iyz="-8.26602224548752E-09"
        izz="1.61404176202361E-07" />
    </inertial>
    <visual>
      <origin
        xyz="0 0 0"
        rpy="0 0 0" />
      <geometry>
        <mesh
          filename="package://smart_arm_description/meshes/thumb_2_link.STL" />
      </geometry>
      <material
        name="">
        <color
          rgba="0.792156862745098 0.819607843137255 0.933333333333333 1" />
      </material>
    </visual>
    <collision>
      <origin
        xyz="0 0 0"
        rpy="0 0 0" />
      <geometry>
        <mesh
          filename="package://smart_arm_description/meshes/thumb_2_link.STL" />
      </geometry>
    </collision>
  </link>

  <link name="middle_1_link">
    <inertial>
      <origin
        xyz="-0.00703243450935939 0.0173092705097653 -0.00798548069738481"
        rpy="0 0 0" />
      <mass
        value="0.00545625911917495" />
      <inertia
        ixx="3.90612953769099E-07"
        ixy="1.77980873893174E-09"
        ixz="-1.58816562130274E-09"
        iyy="3.1304155537832E-07"
        iyz="5.91881896575937E-08"
        izz="4.23235427455386E-07" />
    </inertial>
    <visual>
      <origin
        xyz="0 0 0"
        rpy="0 0 0" />
      <geometry>
        <mesh
          filename="package://smart_arm_description/meshes/middle_1_link.STL" />
      </geometry>
      <material
        name="">
        <color
          rgba="0.792156862745098 0.819607843137255 0.933333333333333 1" />
      </material>
    </visual>
    <collision>
      <origin
        xyz="0 0 0"
        rpy="0 0 0" />
      <geometry>
        <mesh
          filename="package://smart_arm_description/meshes/middle_1_link.STL" />
      </geometry>
    </collision>
  </link>

  <link name="middle_2_link">
    <inertial>
      <origin
        xyz="-0.00632415038644278 0.0115147576834888 -0.000333232809120232"
        rpy="0 0 0" />
      <mass
        value="0.00348681254392789" />
      <inertia
        ixx="1.42495803409043E-07"
        ixy="6.42083738917761E-12"
        ixz="-5.66128771526002E-12"
        iyy="1.23428871201468E-07"
        iyz="1.15346629665482E-08"
        izz="1.42912538138573E-07" />
    </inertial>
    <visual>
      <origin
        xyz="0 0 0"
        rpy="0 0 0" />
      <geometry>
        <mesh
          filename="package://smart_arm_description/meshes/middle_2_link.STL" />
      </geometry>
      <material
        name="">
        <color
          rgba="0.792156862745098 0.819607843137255 0.933333333333333 1" />
      </material>
    </visual>
    <collision>
      <origin
        xyz="0 0 0"
        rpy="0 0 0" />
      <geometry>
        <mesh
          filename="package://smart_arm_description/meshes/middle_2_link.STL" />
      </geometry>
    </collision>
  </link>

  <link name="middle_3_link">
    <inertial>
      <origin
        xyz="-0.00548902061454014 0.0100923850151921 -0.00665149126059028"
        rpy="0 0 0" />
      <mass
        value="0.00288658168120279" />
      <inertia
        ixx="1.10117727071997E-07"
        ixy="-1.55534443640183E-11"
        ixz="5.61060631121711E-11"
        iyy="9.50345739683847E-08"
        iyz="1.46269472075257E-08"
        izz="9.06531551883444E-08" />
    </inertial>
    <visual>
      <origin
        xyz="0 0 0"
        rpy="0 0 0" />
      <geometry>
        <mesh
          filename="package://smart_arm_description/meshes/middle_3_link.STL" />
      </geometry>
      <material
        name="">
        <color
          rgba="0.792156862745098 0.819607843137255 0.933333333333333 1" />
      </material>
    </visual>
    <collision>
      <origin
        xyz="0 0 0"
        rpy="0 0 0" />
      <geometry>
        <mesh
          filename="package://smart_arm_description/meshes/middle_3_link.STL" />
      </geometry>
    </collision>
  </link>

  <link name="pointer_1_link">
    <inertial>
      <origin
        xyz="-0.00627312732951361 0.018037978572514 -0.00248821637768416"
        rpy="0 0 0" />
      <mass
        value="0.00464662673165044" />
      <inertia
        ixx="2.98902869571704E-07"
        ixy="-1.18788072621608E-11"
        ixz="-1.45887482548079E-10"
        iyy="2.21509520954101E-07"
        iyz="1.45876954431312E-08"
        izz="3.41809156243113E-07" />
    </inertial>
    <visual>
      <origin
        xyz="0 0 0"
        rpy="0 0 0" />
      <geometry>
        <mesh
          filename="package://smart_arm_description/meshes/pointer_1_link.STL" />
      </geometry>
      <material
        name="">
        <color
          rgba="0.792156862745098 0.819607843137255 0.933333333333333 1" />
      </material>
    </visual>
    <collision>
      <origin
        xyz="0 0 0"
        rpy="0 0 0" />
      <geometry>
        <mesh
          filename="package://smart_arm_description/meshes/pointer_1_link.STL" />
      </geometry>
    </collision>
  </link>

  <link name="pointer_2_link">
    <inertial>
      <origin
        xyz="-0.0059944646707981 0.00717574917314355 -0.0082394598299626"
        rpy="0 0 0" />
      <mass
        value="0.00296942129713921" />
      <inertia
        ixx="1.0902878077867E-07"
        ixy="4.47795663836142E-15"
        ixz="-6.6980448986755E-12"
        iyy="1.113024196947E-07"
        iyz="6.70365289571796E-09"
        izz="9.24850503494116E-08" />
    </inertial>
    <visual>
      <origin
        xyz="0 0 0"
        rpy="0 0 0" />
      <geometry>
        <mesh
          filename="package://smart_arm_description/meshes/pointer_2_link.STL" />
      </geometry>
      <material
        name="">
        <color
          rgba="0.792156862745098 0.819607843137255 0.933333333333333 1" />
      </material>
    </visual>
    <collision>
      <origin
        xyz="0 0 0"
        rpy="0 0 0" />
      <geometry>
        <mesh
          filename="package://smart_arm_description/meshes/pointer_2_link.STL" />
      </geometry>
    </collision>
  </link>

  <link  name="pointer_3_link">
    <inertial>
      <origin
        xyz="-0.00520292179493784 0.0114659401260275 -0.000387354590101002"
        rpy="0 0 0" />
      <mass
        value="0.00245831065780538" />
      <inertia
        ixx="8.42585897088902E-08"
        ixy="-3.12989101832727E-11"
        ixz="3.05696947302691E-11"
        iyy="6.18419051405367E-08"
        iyz="6.59275537894209E-09"
        izz="8.02382050859085E-08" />
    </inertial>
    <visual>
      <origin
        xyz="0 0 0"
        rpy="0 0 0" />
      <geometry>
        <mesh
          filename="package://smart_arm_description/meshes/pointer_3_link.STL" />
      </geometry>
      <material
        name="">
        <color
          rgba="0.792156862745098 0.819607843137255 0.933333333333333 1" />
      </material>
    </visual>
    <collision>
      <origin
        xyz="0 0 0"
        rpy="0 0 0" />
      <geometry>
        <mesh
          filename="package://smart_arm_description/meshes/pointer_3_link.STL" />
      </geometry>
    </collision>
  </link>


  <xacro:property name="very_small_limit" value="-0.1"/>
  <xacro:property name="proximal_finger_joint_limit" value="1.5707"/>
  <xacro:property name="middle_finger_joint_limit" value="1.3707"/>
  <xacro:property name="distal_finger_joint_limit" value="1.2707"/>

  <joint name="wrist_joint" type="revolute">
    <origin
      xyz="0.00129 0.029395 0.2989"
      rpy="0 0 0" />
    <parent
      link="elbow_link" />
    <child
      link="wrist_link" />
    <axis
      xyz="0 1 0" />
    <limit
      lower="-0.872665"
      upper="0.872665"
      effort="5"
      velocity="1" />
  </joint>
  
  <joint name="wrist_upper_joint" type="revolute">
    <origin
      xyz="0 0.00467160843217863 0.00716947951775644"
      rpy="0 1.48772480012052 -1.5707963267949" />
    <parent
      link="wrist_link" />
    <child
      link="wrist_upper_link" />
    <axis
      xyz="1 0 0" />
    <limit
      lower="${very_small_limit}"
      upper="0.872665"
      effort="5"
      velocity="3" />
  </joint>
  
  <joint name="wrist_middle_joint" type="revolute">
    <origin
      xyz="0 -0.063543 0.017875"
      rpy="0 0.88169 -1.5708" />
    <parent
      link="wrist_link" />
    <child
      link="wrist_middle_link" />
    <axis
      xyz="-1 0 0" />
    <limit
      lower="${very_small_limit}"
      upper="${-very_small_limit}"
      effort="5"
      velocity="2" />
  </joint>

  <joint name="wrist_lower_joint" type="revolute">
    <origin
      xyz="0 -0.063543 0.017875"
      rpy="0 0.88169 -1.5708" />
    <parent
      link="wrist_link" />
    <child
      link="wrist_lower_link" />
    <axis
      xyz="-1 0 0" />
    <limit
      lower="${very_small_limit}"
      upper="${-very_small_limit}"
      effort="5"
      velocity="5" />
  </joint>




  <joint name="thumb_1_joint" type="revolute">
    <origin
      xyz="-0.041192 0.017697 -0.032051"
      rpy="-1 0.31508 0.77256" />
    <parent
      link="wrist_upper_link" />
    <child
      link="thumb_1_link" />
    <axis
      xyz="1 0 0" />
    <limit
      lower="${very_small_limit}"
      upper="0.8720"
      effort="5"
      velocity="4" />
  </joint>

  <joint name="thumb_2_joint" type="revolute">
    <origin
      xyz="-0.000865682899112985 0.0214109109835155 0.0182563649065549"
      rpy="0 0 0" />
    <parent
      link="thumb_1_link" />
    <child
      link="thumb_2_link" />
    <axis
      xyz="1 0 0" />
    <limit
      lower="${very_small_limit}"
      upper="1.39626"
      effort="5"
      velocity="4" />
  </joint>




  <joint name="pinky_1_joint" type="revolute">
    <origin
      xyz="-0.043751 0.0091577 0.05009"
      rpy="-1.5908 -0.61679 0.12536" />
    <parent
      link="wrist_lower_link" />
    <child
      link="pinky_1_link" />
    <axis
      xyz="-1 0 0" />
    <limit
      lower="${very_small_limit}"
      upper="${proximal_finger_joint_limit}"
      effort="5"
      velocity="2" />
  </joint>

  <joint name="pinky_2_joint" type="revolute">
    <origin
      xyz="-0.00023197 -0.029503 0.0045349"
      rpy="3.226 0.13765 -0.015931" />
    <parent
      link="pinky_1_link" />
    <child
      link="pinky_2_link" />
    <axis
      xyz="-1 0 0" />
    <limit
      lower="${very_small_limit}"
      upper="${middle_finger_joint_limit}"
      effort="5"
      velocity="3" />
  </joint>
  
  <joint name="pinky_3_joint" type="revolute">
    <origin
      xyz="-0.0011308 0.018906 -0.0033205"
      rpy="0.24361 0.13856 0" />
    <parent
      link="pinky_2_link" />
    <child
      link="pinky_3_link" />
    <axis
      xyz="-1 0 0" />
    <limit
      lower="${very_small_limit}"
      upper="${distal_finger_joint_limit}"
      effort="5"
      velocity="2" />
  </joint>




  <joint name="ring_1_joint" type="revolute">
    <origin
      xyz="-0.069801 0.0076347 0.041426"
      rpy="1.5238 -0.78078 0.17561" />
    <parent
      link="wrist_middle_link" />
    <child
      link="ring_1_link" />
    <axis
      xyz="-1 0 0" />
    <limit
      lower="${very_small_limit}"
      upper="${proximal_finger_joint_limit}"
      effort="5"
      velocity="2" />
  </joint>

  <joint name="ring_2_joint" type="revolute">
    <origin
      xyz="-0.00027831 0.035204 -0.0065715"
      rpy="-0.08653 0 0" />
    <parent
      link="ring_1_link" />
    <child
      link="ring_2_link" />
    <axis
      xyz="-1 0 0" />
    <limit
      lower="${very_small_limit}"
      upper="${middle_finger_joint_limit}"
      effort="5"
      velocity="2" />
  </joint>

  <joint name="ring_3_joint" type="revolute">
    <origin
      xyz="-0.000793430469754296 0.0229811955997807 -0.00184137348495991"
      rpy="-0.183278724594159 0 0" />
    <parent
      link="ring_2_link" />
    <child
      link="ring_3_link" />
    <axis
      xyz="-1 0 0" />
    <limit
      lower="${very_small_limit}"
      upper="${distal_finger_joint_limit}"
      effort="5"
      velocity="2" />
  </joint>



  <joint name="middle_1_joint" type="revolute">
    <origin
      xyz="0.000525788242336553 -0.0208949853387586 0.107469880482186"
      rpy="1.8507963267949 0 -1.5707963267949" />
    <parent
      link="wrist_link" />
    <child
      link="middle_1_link" />
    <axis
      xyz="-1 0 0" />
    <limit
      lower="${very_small_limit}"
      upper="${proximal_finger_joint_limit}"
      effort="5"
      velocity="5" />
  </joint>

  <joint name="middle_2_joint"  type="revolute">
    <origin
      xyz="-0.0011154 0.03449 -0.015386"
      rpy="-0.2614 0 0.023821" />
    <parent
      link="middle_1_link" />
    <child
      link="middle_2_link" />
    <axis
      xyz="-1 0 0" />
    <limit
      lower="${very_small_limit}"
      upper="${middle_finger_joint_limit}"
      effort="5"
      velocity="4" />
  </joint>

  <joint name="middle_3_joint" type="revolute">
    <origin
      xyz="-0.00083707 0.024267 -0.0016433"
      rpy="0.45093 0 0" />
    <parent
      link="middle_2_link" />
    <child
      link="middle_3_link" />
    <axis
      xyz="-1 0 0" />
    <limit
      lower="${very_small_limit}"
      upper="${distal_finger_joint_limit}"
      effort="4"
      velocity="5" />
  </joint>



  <joint name="pointer_1_joint" type="revolute">
    <origin
      xyz="0.000525021796397782 0.00639325128397639 0.103423200281556"
      rpy="1.5707963267949 -0.0968623019535048 -1.5707963267949" />
    <parent
      link="wrist_link" />
    <child
      link="pointer_1_link" />
    <axis
      xyz="-1 0 0" />
    <limit
      lower="${very_small_limit}"
      upper="${proximal_finger_joint_limit}"
      effort="5"
      velocity="2" />
  </joint>

  <joint name="pointer_2_joint" type="revolute">
    <origin
      xyz="-0.00027831 0.03552 -0.0045641"
      rpy="0.840000 0 0" />
    <parent
      link="pointer_1_link" />
    <child
      link="pointer_2_link" />
    <axis
      xyz="-1 0 0" />
    <limit
      lower="${very_small_limit}"
      upper="${middle_finger_joint_limit}"
      effort="5"
      velocity="3" />
  </joint>

  <joint name="pointer_3_joint" type="revolute">
    <origin
      xyz="-0.00079343 0.014451 -0.017972"
      rpy="-0.91742 0 0" />
    <parent
      link="pointer_2_link" />
    <child
      link="pointer_3_link" />
    <axis
      xyz="-1 0 0" />
    <limit
      lower="${very_small_limit}"
      upper="${distal_finger_joint_limit}"
      effort="5"
      velocity="2" />
  </joint>

</robot>